Workbook

Sheet Data
A1: Ticker | B1: Year
A2: PSGO | B2: 2024
A3: ACRO | B3: 2024
A4: PGUN | B4: 2024
A5: CITA | B5: 2024
A6: DATA | B6: 2024
A7: RMKE | B7: 2023
A8: MITI | B8: 2024
A9: AMMN | B9: 2023
A10: SSMS | B10: 2023
A11: SMBR | B11: 2024
A12: MITI | B12: 2023
A13: CHIP | B13: 2024
... A317: MANG | B317: 2024

Sheet winsor
A1: Ticker | B1: Year | C1: Report Date | D1: DSRI | E1: GMI | F1: AQI | G1: SGI | H1: DEPI | I1: SGAI | J1: LVGI | K1: TATA | L1: M_Score | M1: Prediction | N1: Volatilitas 30 Hari SEBELUM | O1: Volatilitas 30 Hari Setelah | P1: Positive_Sum | Q1: Negative_Sum | R1: Total_Matched_Words | S1: Total_Word | T1: FLAG POTENTIAL FRAUD | U1: Unnamed: 20 | V1: Unnamed: 21
A2: BTEK | B2: 2024 | C2: 2025-04-07 | D2: 5.2614831 | E2: 0.98117562 | F2: 1.0716075 | G2: 3.2319772 | H2: 0.58539362 | I2: 0.44287246 | J2: 1.0824337 | K2: 0.16648618 | L2: 4.9261508 | M2: Potential Manipulator | N2: 1.6068367 | O2: 1.8976995 | P2: 1357 | Q2: 1672 | R2: 942 | S2: 5928 | T2: 0 | W2: =VLOOKUP(L2,ML_Data!I:K,1,FALSE) -> #N/A
A3: VERN | B3: 2024 | C3: 2025-03-27 | D3: 2.5028215 | E3: 1.0178223 | F3: 3.3699971 | G3: 0.56834986 | H3: 4.6092044 | I3: 2.2677311 | J3: 0.99925147 | K3: -0.16444277 | L3: 4.9261508 | M3: Potential Manipulator | N3: 0.62395218 | O3: 0.60534969 | P3: 3069 | Q3: 2450 | R3: 1756 | S3: 12747 | T3: 0 | W3: =VLOOKUP(L3,ML_Data!I:K,1,FALSE) -> #N/A
A4: SOUL | B4: 2023 | C4: 2024-04-20 | D4: 5.2614831 | E4: 1.1032514 | F4: 0.4428743 | G4: 1.0505544 | H4: 1.0846158 | I4: 1.4536945 | J4: 0.98786998 | K4: -0.026305007 | L4: 4.9261508 | M4: Potential Manipulator | N4: 0.78634972 | O4: 0.82178642 | P4: 933 | Q4: 804 | R4: 556 | S4: 3272 | T4: 0 | W4: =VLOOKUP(L4,ML_Data!I:K,1,FALSE) -> #N/A
A5: ENVY | B5: 2023 | C5: 2024-04-03 | D5: 2.0010364 | E5: 1.1551197 | F5: 0.3296093 | G5: 1.2818399 | H5: 0.30677072 | I5: 0.84430338 | J5: 1.2788472 | K5: 0.28650521 | L5: 4.9261508 | M5: Potential Manipulator | N5: 0 | O5: 0 | P5: 1213 | Q5: 1607 | R5: 870 | S5: 5296 | T5: 0 | W5: =VLOOKUP(L5,ML_Data!I:K,1,FALSE) -> #N/A
A6: MIRA | B6: 2024 | C6: 2025-03-28 | D6: 1.1629978 | E6: 4.9419648 | F6: 0.95721601 | G6: 0.85504681 | H6: 1.2739952 | I6: 0.91671756 | J6: 0.99405124 | K6: 0.012481008 | L6: 4.9261508 | M6: Potential Manipulator | N6: 1.2844342 | O6: 0.83969069 | P6: 882 | Q6: 1022 | R6: 589 | S6: 3701 | T6: 0 | W6: =VLOOKUP(L6,ML_Data!I:K,1,FALSE) -> #N/A
A7: DPUM | B7: 2023 | C7: 2024-04-09 | D7: 0.88783442 | E7: 4.9419648 | F7: 0.95678822 | G7: 1.2710702 | H7: 0.88467197 | I7: 0.8345176 | J7: 1.0387299 | K7: 0.10947394 | L7: 4.9261508 | M7: Potential Manipulator | N7: 0.59562013 | O7: 0.793711 | P7: 2092 | Q7: 2190 | R7: 1349 | S7: 8615 | T7: 0 | W7: =VLOOKUP(L7,ML_Data!I:K,1,FALSE) -> #N/A
A8: POLY | B8: 2023 | C8: 2024-08-21 | D8: 1.3516499 | E8: 4.9419648 | F8: 1.0305567 | G8: 0.73353317 | H8: 0.8767842 | I8: 1.2474276 | J8: 1.0663774 | K8: 0.096001972 | L8: 3.2214868 | M8: Potential Manipulator | N8: 0.66382934 | O8: 0.72370549 | P8: 1327 | Q8: 1700 | R8: 941 | S8: 5786 | T8: 0 | W8: =VLOOKUP(L8,ML_Data!I:K,1,FALSE) -> #N/A
A9: BEEF | B9: 2024 | C9: 2025-04-03 | D9: 0.43910263 | E9: 2.808423 | F9: 0.61466233 | G9: 3.971747 | H9: 1.024419 | I9: 0.18033619 | J9: 0.95571403 | K9: -0.25537659 | L9: 3.0690293 | M9: Potential Manipulator | N9: 0.77117599 | O9: 0.75012554 | P9: 2909 | Q9: 2349 | R9: 1655 | S9: 11534 | T9: 0 | W9: =VLOOKUP(L9,ML_Data!I:K,1,FALSE) -> #N/A
A10: HRUM | B10: 2023 | C10: 2024-05-17 | D10: 5.2614831 | E10: 1.4490455 | F10: 0.70166786 | G10: 1.0233101 | H10: 1.5428776 | I10: 0.77750331 | J10: 1.0724107 | K10: 0.032186887 | L10: 2.5098538 | M10: Potential Manipulator | N10: 0.67503185 | O10: 0.53200775 | P10: 5663 | Q10: 4942 | R10: 3406 | S10: 20787 | T10: 0 | W10: =VLOOKUP(L10,ML_Data!I:K,1,FALSE) -> #N/A
A11: ACRO | B11: 2023 | C11: 2024-03-30 | D11: 5.2614831 | E11: 0.60535537 | F11: 1.0138032 | G11: 0.75136397 | H11: 1.0740517 | I11: 0.78087208 | J11: 1.0014237 | K11: -0.0041051531 | L11: 2.0886801 | M11: Potential Manipulator | N11: 1.0329147 | O11: 0.70824876 | P11: 2466 | Q11: 2498 | R11: 1574 | S11: 11578 | T11: 0 | W11: =VLOOKUP(L11,ML_Data!I:K,1,FALSE) -> #N/A
A12: PKPK | B12: 2024 | C12: 2025-03-25 | D12: 1.8935115 | E12: 0.28485186 | F12: 2.9395632 | G12: 3.971747 | H12: 2.5567099 | I12: 0.54616891 | J12: 1.0011283 | K12: 0.031968388 | L12: 2.0396743 | M12: Potential Manipulator | N12: 0.34320414 | O12: 0.34996849 | P12: 2808 | Q12: 3135 | R12: 1862 | S12: 10531 | T12: 0 | W12: =VLOOKUP(L12,ML_Data!I:K,1,FALSE) -> #N/A
A13: HOPE | B13: 2024 | C13: 2025-04-09 | D13: 5.2614831 | E13: -0.30155764 | F13: 1.0613751 | G13: 0.50186582 | H13: 1.5844049 | I13: 1.4735544 | J13: 0.99582826 | K13: 0.12878711 | L13: 1.2602625 | M13: Potential Manipulator | N13: 1.0735039 | O13: 0.7738219 | P13: 1833 | Q13: 2113 | R13: 1248 | S13: 8909 | T13: 0 | W13: =VLOOKUP(L13,ML_Data!I:K,1,FALSE) -> #N/A
... A29: MHKI | B29: 2023 | C29: 2024-07-09 | D29: 1.4113218 | E29: 0.86591093 | F29: 0.99890367 | G29: 1.1221345 | H29: 0.95470509 | I29: 1.0951211 | J29: 0.99778799 | K29: 0.28650521 | L29: -0.19773133 | M29: Potential Manipulator | N29: 1.8753422 | O29: 0.58050118 | P29: 1257 | Q29: 1279 | R29: 812 | S29: 6451 | T29: 0 | W29: =VLOOKUP(L29,ML_Data!I:K,1,FALSE) -> #N/A
A30: CMPP | B30: 2024 | C30: 2025-03-27 | D30: 2.6169498 | E30: 1.2223385 | F30: 0.9991433 | G30: 1.1990259 | H30: 0.91442383 | I30: 1.00908 | J30: 1.1643465 | K30: 0.11250918 | L30: -0.23654032 | M30: Potential Manipulator | N30: 0.39874408 | O30: 0.4541576 | P30: 3052 | Q30: 3604 | R30: 2134 | S30: 14644 | T30: 0 | V30: 1.0025451 | W30: =VLOOKUP(L30,ML_Data!I:K,1,FALSE) -> #N/A
A31: NCKL | B31: 2023 | C31: 2024-04-01 | D31: 1.4931589 | E31: 1.4086825 | F31: 0.90429078 | G31: 2.4935173 | H31: 0.4623679 | I31: 0.6583954 | J31: 0.90246152 | K31: 0.030689443 | L31: -0.34453924 | M31: Potential Manipulator | N31: 0.52840572 | O31: 0.43112291 | P31: 4145 | Q31: 4233 | R31: 2785 | S31: 19836 | T31: 0 | W31: =VLOOKUP(L31,ML_Data!I:K,1,FALSE) -> #N/A
A32: BRMS | B32: 2023 | C32: 2024-04-02 | D32: 0.26404663 | E32: 1.0016721 | F32: 1.0473312 | G32: 3.971747 | H32: 0.2933856 | I32: 0.41546053 | J32: 0.98234766 | K32: -0.00046888452 | L32: -0.43488542 | M32: Potential Manipulator | N32: 0.34822751 | O32: 0.42453365 | P32: 1814 | Q32: 1573 | R32: 1118 | S32: 7213 | T32: 0 | W32: =VLOOKUP(L32,ML_Data!I:K,1,FALSE) -> #N/A
A33: GEMS | B33: 2023 | C33: 2024-03-30 | D33: 1.5352025 | E33: 1.1398379 | F33: 1.8717545 | G33: 0.99379167 | H33: 1.3614344 | I33: 1.1076906 | J33: 0.94398715 | K33: 0.22274275 | L33: -0.48355654 | M33: Potential Manipulator | N33: 0.094867235 | O33: 0.12160856 | P33: 1857 | Q33: 1537 | R33: 1174 | S33: 8578 | T33: 0 | W33: =VLOOKUP(L33,ML_Data!I:K,1,FALSE) -> #N/A
A34: CMPP | B34: 2023 | C34: 2024-05-13 | D34: 0.50043427 | E34: 3.2815512 | F34: 1.1228068 | G34: 1.7524865 | H34: 1.0135328 | I34: 1.00908 | J34: 1.0090495 | K34: 0.11315795 | L34: -0.48760811 | M34: Potential Manipulator | N34: 0.71375785 | O34: 0.18247843 | P34: 2500 | Q34: 2589 | R34: 1642 | S34: 11970 | T34: 0 | V34: 1.009014 | W34: =VLOOKUP(L34,ML_Data!I:K,1,FALSE) -> #N/A
A35: MYOH | B35: 2023 | C35: 2024-05-06 | D35: 2.5284233 | E35: 0.9939357 | F35: 2.4094536 | G35: 0.94824563 | H35: 2.1853024 | I35: 1.156761 | J35: 1.0713151 | K35: -0.0073424492 | L35: -0.50212669 | M35: Potential Manipulator | N35: 0.26403411 | O35: 0.19493942 | P35: 3677 | Q35: 3435 | R35: 2286 | S35: 15420 | T35: 0 | W35: =VLOOKUP(L35,ML_Data!I:K,1,FALSE) -> #N/A
A36: LSIP | B36: 2024 | C36: 2025-02-28 | D36: 3.2486782 | E36: 0.6291361 | F36: 0.87183793 | G36: 1.0889299 | H36: 0.95598646 | I36: 1.0484437 | J36: 0.99593764 | K36: 0.01500655 | L36: -0.52133403 | M36: Potential Manipulator | N36: 0.25815475 | O36: 0.58271112 | P36: 1740 | Q36: 2212 | R36: 1263 | S36: 8260 | T36: 0 | W36: =VLOOKUP(L36,ML_Data!I:K,1,FALSE) -> #N/A
A37: ISAP | B37: 2024 | C37: 2025-03-25 | D37: 4.0611437 | E37: 0.56664556 | F37: 0.96327874 | G37: 0.46487132 | H37: 0.918372 | I37: 1.7650022 | J37: 0.99830272 | K37: 0.00057911713 | L37: -0.52243202 | M37: Potential Manipulator | N37: 0.9915763 | O37: 1.0073555 | P37: 1725 | Q37: 1698 | R37: 1107 | S37: 8537 | T37: 0 | W37: =VLOOKUP(L37,ML_Data!I:K,1,FALSE) -> #N/A
A38: MANG | B38: 2023 | C38: 2024-05-22 | D38: 0.30026648 | E38: 0.18286266 | F38: 0.97162266 | G38: 3.971747 | H38: 0.75868434 | I38: 0.18033619 | J38: 1 | K38: -0.0073221892 | L38: -0.54820157 | M38: Potential Manipulator | N38: 0.98787905 | O38: 0.69488537 | P38: 1733 | Q38: 1788 | R38: 1106 | S38: 7328 | T38: 0 | W38: =VLOOKUP(L38,ML_Data!I:K,1,FALSE) -> #N/A
A39: SRIL | B39: 2023 | C39: 2024-08-22 | D39: 1.5387437 | E39: 2.156484 | F39: 1.0982342 | G39: 0.61971629 | H39: 1.3934317 | I39: 0.96302106 | J39: 1.2214275 | K39: 0.243371 | L39: -0.55532759 | M39: Potential Manipulator | N39: 0 | O39: 0 | P39: 3843 | Q39: 4386 | R39: 2612 | S39: 17169 | T39: 0 | W39: =VLOOKUP(L39,ML_Data!I:K,1,FALSE) -> #N/A
A40: MSKY | B40: 2024 | C40: 2025-03-18 | D40: 0.80699168 | E40: 4.9419648 | F40: 1.038472 | G40: 0.94970778 | H40: 0.8279596 | I40: 1.1689887 | J40: 0.95010405 | K40: -0.0091147134 | L40: -0.61039186 | M40: Potential Manipulator | N40: 0.57697097 | O40: 0.44870785 | P40: 1378 | Q40: 1632 | R40: 922 | S40: 5420 | T40: 0 | W40: =VLOOKUP(L40,ML_Data!I:K,1,FALSE) -> #N/A
A41: NICE | B41: 2023 | C41: 2024-03-29 | D41: 2.6108243 | E41: 1.4884887 | F41: 1.2466702 | G41: 1.037454 | H41: 1.0395973 | I41: 1.7735005 | J41: 0.99876525 | K41: 0.010770296 | L41: -0.68474629 | M41: Potential Manipulator | N41: 1.0097577 | O41: 0.96036911 | P41: 2509 | Q41: 2711 | R41: 1627 | S41: 10947 | T41: 0 | W41: =VLOOKUP(L41,ML_Data!I:K,1,FALSE) -> #N/A
A42: FOOD | B42: 2024 | C42: 2025-03-27 | D42: 1.1881679 | E42: 1.5686565 | F42: 0.3296093 | G42: 1.0608337 | H42: 0.44482139 | I42: 0.69536066 | J42: 1.0600622 | K42: 0.28650521 | L42: -0.7607777 | M42: Potential Manipulator | N42: 0.20715272 | O42: 0.37171081 | P42: 1446 | Q42: 1805 | R42: 1053 | S42: 7734 | T42: 0 | W42: =VLOOKUP(L42,ML_Data!I:K,1,FALSE) -> #N/A
A43: DOOH | B43: 2023 | C43: 2024-05-13 | D43: 2.0210853 | E43: 3.0390417 | F43: 0.36947266 | G43: 3.971747 | H43: 0.40717049 | I43: 1.5429634 | J43: 0.99983617 | K43: -0.29008909 | L43: -0.7844644 | M43: Potential Manipulator | N43: 0.63716894 | O43: 0.42549547 | P43: 2667 | Q43: 2603 | R43: 1711 | S43: 12322 | T43: 0 | W43: =VLOOKUP(L43,ML_Data!I:K,1,FALSE) -> #N/A
A44: WMUU | B44: 2023 | C44: 2024-05-07 | D44: 4.5943459 | E44: -0.25478206 | F44: 0.87931971 | G44: 0.34937905 | H44: 0.95438747 | I44: 3.9408828 | J44: 1.1223664 | K44: 0.088600087 | L44: -0.79081143 | M44: Potential Manipulator | N44: 1.199926 | O44: 1.1308349 | P44: 1265 | Q44: 1624 | R44: 935 | S44: 6726 | T44: 0 | W44: =VLOOKUP(L44,ML_Data!I:K,1,FALSE) -> #N/A
A45: LOPI | B45: 2023 | C45: 2024-03-27 | D45: 4.0874105 | E45: 1.6466385 | F45: 0.5401186 | G45: 1.1557686 | H45: 1.3275236 | I45: 1.00908 | J45: 0.94664734 | K45: -0.29008909 | L45: -0.80743937 | M45: Potential Manipulator | N45: 0.66581609 | O45: 0.80326529 | P45: 1808 | Q45: 1860 | R45: 1174 | S45: 9411 | T45: 0 | W45: =VLOOKUP(L45,ML_Data!I:K,1,FALSE) -> #N/A
A46: KKGI | B46: 2023 | C46: 2024-03-26 | D46: 1.7004674 | E46: 1.6128247 | F46: 0.98579532 | G46: 1.1544851 | H46: 1.1812663 | I46: 0.81459812 | J46: 0.99582866 | K46: 0.10904201 | L46: -0.8156302 | M46: Potential Manipulator | N46: 0.15102076 | O46: 0.50877417 | P46: 2992 | Q46: 3273 | R46: 2029 | S46: 13288 | T46: 0 | W46: =VLOOKUP(L46,ML_Data!I:K,1,FALSE) -> #N/A
... A91: SURI | B91: 2023 | C91: 2024-04-23 | D91: 3.158755 | E91: 0.90062679 | F91: 1.1435058 | G91: 0.87561173 | H91: 1.9339245 | I91: 1.2013871 | J91: 0.98284871 | K91: -0.2109841 | L91: -1.5082158 | M91: Potential Manipulator | N91: 1.3114426 | O91: 1.8500204 | P91: 2607 | Q91: 2757 | R91: 1717 | S91: 11296 | T91: 0 | W91: =VLOOKUP(L91,ML_Data!I:K,1,FALSE) -> #N/A
A92: MINE | B92: 2024 | C92: 2025-04-11 | D92: 1.6874545 | E92: 0.91807458 | F92: 0.82176076 | G92: 1.2042493 | H92: 0.83783504 | I92: 1.8808693 | J92: 1.0156874 | K92: 0.094779252 | L92: -1.5124329 | M92: Potential Manipulator | O92: 0.8512606 | P92: 3104 | Q92: 2639 | R92: 1835 | S92: 12166 | T92: 0 | W92: =VLOOKUP(L92,ML_Data!I:K,1,FALSE) -> #N/A
A93: PJAA | B93: 2023 | C93: 2024-02-21 | D93: 1.521891 | E93: 1.0380398 | F93: 1.1603639 | G93: 1.3298486 | H93: 1.1939915 | I93: 0.83745419 | J93: 1.0067942 | K93: 0.0089428918 | L93: -1.5308743 | M93: Potential Manipulator | N93: 0.24172726 | O93: 0.19652789 | P93: 4005 | Q93: 3833 | R93: 2577 | S93: 17708 | T93: 0 | W93: =VLOOKUP(L93,ML_Data!I:K,1,FALSE) -> #N/A
A94: MITI | B94: 2024 | C94: 2025-03-19 | D94: 1.672944 | E94: 1.5842618 | F94: 0.95633323 | G94: 0.95386303 | H94: 0.91466571 | I94: 0.99313853 | J94: 0.99599546 | K94: 0.016006686 | L94: -1.5436254 | M94: Potential Manipulator | N94: 0.76726586 | O94: 0.40910817 | P94: 2046 | Q94: 1885 | R94: 1274 | S94: 10600 | T94: 1 | W94: =VLOOKUP(L94,ML_Data!I:K,1,FALSE) -> -1.5436254
A95: POLA | B95: 2023 | C95: 2024-04-29 | D95: 3.0756995 | E95: 1.0064875 | F95: 1.1242233 | G95: 0.34937905 | H95: 0.979015 | I95: 2.6913994 | J95: 1 | K95: -0.02303455 | L95: -1.5444132 | M95: Potential Manipulator | N95: 0.69082109 | O95: 1.0624044 | P95: 1398 | Q95: 1569 | R95: 959 | S95: 7016 | T95: 0 | W95: =VLOOKUP(L95,ML_Data!I:K,1,FALSE) -> #N/A
A96: SURI | B96: 2024 | C96: 2025-04-08 | D96: 0.58119855 | E96: 2.0367658 | F96: 1.6396898 | G96: 1.4277171 | H96: 1.6020745 | I96: 0.6495784 | J96: 1.000481 | K96: -0.0016833153 | L96: -1.5564491 | M96: Potential Manipulator | N96: 0 | O96: 0.77523159 | P96: 1990 | Q96: 2124 | R96: 1337 | S96: 9221 | T96: 0 | W96: =VLOOKUP(L96,ML_Data!I:K,1,FALSE) -> #N/A
A97: PTMP | B97: 2024 | C97: 2025-03-29 | D97: 1.4261912 | E97: 0.93753582 | F97: 1.3799297 | G97: 1.2569379 | H97: 4.6092044 | I97: 1.069505 | J97: 0.98372912 | K97: -0.053170273 | L97: -1.5773273 | M97: Potential Manipulator | N97: 0.45099371 | O97: 0.24053215 | P97: 2431 | Q97: 2372 | R97: 1543 | S97: 10341 | T97: 0 | W97: =VLOOKUP(L97,ML_Data!I:K,1,FALSE) -> #N/A
A98: TOPS | B98: 2023 | C98: 2024-06-10 | D98: 0.68191991 | E98: 2.7853497 | F98: 0.94336283 | G98: 0.45065993 | H98: 0.93384925 | I98: 1.4574798 | J98: 1.1966196 | K98: 0.19510274 | L98: -1.5805646 | M98: Potential Manipulator | N98: 1.8753422 | O98: 1.8976995 | P98: 1822 | Q98: 2264 | R98: 1272 | S98: 8132 | T98: 0 | W98: =VLOOKUP(L98,ML_Data!I:K,1,FALSE) -> #N/A
A99: TBLA | B99: 2023 | C99: 2024-03-29 | D99: 1.969148 | E99: 1.0988774 | F99: 1.0197932 | G99: 0.92386333 | H99: 1.0687622 | I99: 0.93612951 | J99: 1.023895 | K99: -0.00053551852 | L99: -1.5875201 | M99: Potential Manipulator | N99: 0.167104 | O99: 0.31705241 | P99: 5650 | Q99: 6063 | R99: 3720 | S99: 24988 | T99: 0 | W99: =VLOOKUP(L99,ML_Data!I:K,1,FALSE) -> #N/A
...

Sheet ML_Data
A1: DSRI | B1: GMI | C1: AQI | D1: SGI | E1: DEPI | F1: SGAI | G1: LVGI | H1: TATA | I1: M_Score | J1: MScorePred | K1: VolatilitasD-30 | L1: Negative_Tone | M1: Positive_Tone | N1: Subjectivity_Ratio | O1: FLAG POTENTIAL FRAUD
A2: 0.77221941 | B2: -0.95649993 | C2: 1.4342966 | D2: 0.8140364 | E2: 1.2143998 | F2: 1.2844745 | G2: 0.99033923 | H2: 0.10193152 | I2: -4.2682764 | J2: 0 | K2: 0.22394528 | L2: 0.22613297 | M2: 0.1957672 | N2: 0.13561077 | O2: 1
A3: 0.24254206 | B3: 0.44287214 | C3: 0.7997323 | D3: 1.1123324 | E3: 3.3282237 | F3: 4.0224962 | G3: 0.97860049 | H3: -0.03133097 | I3: -4.0343709 | J3: 0 | K3: 1.0103897 | L3: 0.20842309 | M3: 0.24407583 | N3: 0.14519604 | O3: 1
A4: 0.96665047 | B4: 1.1919915 | C4: 0.93420329 | D4: 0.87505767 | E4: 0.92669519 | F4: 1.2053104 | G4: 1.0302397 | H4: 0.030456274 | I4: -2.4584674 | J4: 0 | K4: 1.8753422 | L4: 0.25203572 | M4: 0.19950092 | N4: 0.13737851 | O4: 0
A5: 1.3630564 | B5: 0.77739021 | C5: 0.5584764 | D5: 0.97315415 | E5: 0.66239527 | F5: 1.4372544 | G5: 1.0622748 | H5: -0.18076276 | I5: -3.4460333 | J5: 0 | K5: 1.8753422 | L5: 0.23769539 | M5: 0.23239891 | N5: 0.14817207 | O5: 0
A6: 1.2766683 | B6: 0.96294959 | C6: 0.82151651 | D6: 0.89147767 | E6: 0.85833316 | F6: 1.1395279 | G6: 0.9444283 | H6: -0.053813656 | I6: -2.6878497 | J6: 0 | K6: 1.7671082 | L6: 0.29780072 | M6: 0.24663375 | N6: 0.17280072 | O6: 0
A7: 0.72930354 | B7: 0.56766767 | C7: 1.0360037 | D7: 1.4834599 | E7: 1.051586 | F7: 1.0625529 | G7: 0.97001744 | H7: -0.036714484 | I7: -2.67833 | J7: 0 | K7: 0.49845215 | L7: 0.23285698 | M7: 0.24770134 | N7: 0.15520106 | O7: 1
A8: 1.2502975 | B8: 0.95099945 | C8: 1.0057227 | D8: 1.4966898 | E8: 1.2936253 | F8: 0.88389183 | G8: 0.99501711 | H8: -0.16877805 | I8: -2.5645849 | J8: 0 | K8: 1.6469133 | L8: 0.22706943 | M8: 0.24241382 | N8: 0.14917773 | O8: 0
A9: 1.3956957 | B9: 0.58663389 | C9: 0.7693399 | D9: 1.2318861 | E9: 0.92830812 | F9: 0.87543119 | G9: 0.99581169 | H9: -0.025118 | I9: -2.3235377 | J9: 0 | K9: 0.36225643 | L9: 0.25373915 | M9: 0.25666771 | N9: 0.16358122 | O9: 1
A10: 1.1386233 | B10: 0.86207153 | C10: 2.8979633 | D10: 0.80380102 | E10: 1.3806132 | F10: 1.0331461 | G10: 1 | H10: -0.1059065 | I10: -2.2909923 | J10: 0 | K10: 1.6030533 | L10: 0.2463785 | M10: 0.23598131 | N10: 0.15221963 | O10: 0
A11: 0.24254206 | B11: -0.016733524 | C11: 0.97710603 | D11: 0.89451435 | E11: 0.86535232 | F11: 0.40867286 | G11: 0.99628286 | H11: -0.055931965 | I11: -4.1408692 | J11: 0 | K11: 1.4478683 | L11: 0.24661406 | M11: 0.18949476 | N11: 0.13979508 | O11: 0
A12: 1.0920782 | B12: 0.93516736 | C12: 0.55455794 | D12: 1.1246338 | E12: 0.2933856 | F12: 1.1440017 | G12: 0.99452618 | H12: -0.29008909 | I12: -3.9750361 | J12: 0 | K12: 1.3052779 | L12: 0.22697958 | M12: 0.24238624 | N12: 0.15254389 | O12: 0
A13: 1.1039563 | B13: 0.015449351 | C13: 0.97653484 | D13: 0.91493986 | E13: 1.0527745 | F13: 1.5923139 | G13: 1.0514812 | H13: 0.028283143 | I13: -2.9698629 | J13: 0 | K13: 1.3044051 | L13: 0.31777266 | M13: 0.18568139 | N13: 0.1500942 | O13: 0
... A317: 1.1208539 | B317: -0.95649993 | C317: 0.87802377 | D317: 0.64664943 | E317: 0.92441921 | F317: 1.5804381 | G317: 1.028291 | H317: 0.031024931 | I317: -4.016769 | J317: 0 | K317: 0 | L317: 0.17742544 | M317: 0.1597584 | N317: 0.10147225 | O317: 0
